2014-07-13 13:38:52,312 - authorization - ERROR - Failed to open file
Traceback (most recent call last):
  File "C:\Users\Windows\Desktop\twitterAnalyzer\CrawlingModule\authorization.py", line 56, in oauth_login
    oauth_token, oauth_token_secret = read_token_file(OAUTH_FILE)
  File "C:\Python27\lib\site-packages\twitter\oauth.py", line 74, in read_token_file
    f = open(filename)
IOError: [Errno 2] No such file or directory: 'C:/Users/Windows/Desktop/twitterAnalyzer/CrawlingModule/Resources/twitter_oauth.txt'
2014-07-13 14:12:49,407 - search_tweets - ERROR - Failed to find attribute (WARRNING: might throw this exception for some results while searching in the loop)
Traceback (most recent call last):
  File "C:\Users\Windows\Desktop\twitterAnalyzer\CrawlingModule\search_tweets.py", line 170, in twitter_search
    next_results = search_results['search_metadata']['next_results']
KeyError: 'next_results'
2014-07-13 14:20:06,545 - search_tweets - ERROR - Failed to find attribute (WARRNING: might throw this exception for some results while searching in the loop)
Traceback (most recent call last):
  File "C:\Users\Windows\Desktop\twitterAnalyzer\CrawlingModule\search_tweets.py", line 170, in twitter_search
    next_results = search_results['search_metadata']['next_results']
KeyError: 'next_results'
2014-07-13 14:23:39,171 - search_tweets - ERROR - Failed to find attribute (WARRNING: might throw this exception for some results while searching in the loop)
Traceback (most recent call last):
  File "C:\Users\Windows\Desktop\twitterAnalyzer\CrawlingModule\search_tweets.py", line 170, in twitter_search
    next_results = search_results['search_metadata']['next_results']
KeyError: 'next_results'
2014-07-13 15:16:09,381 - search_tweets - ERROR - Failed to find attribute (WARRNING: might throw this exception for some results while searching in the loop)
Traceback (most recent call last):
  File "C:\Users\Windows\Desktop\twitterAnalyzer\CrawlingModule\search_tweets.py", line 161, in twitter_search
    next_results = search_results['search_metadata']['next_results']
KeyError: 'next_results'
2014-07-15 11:10:26,611 - search_tweets - ERROR - Failed to find attribute (WARRNING: might throw this exception for some results while searching in the loop)
Traceback (most recent call last):
  File "C:\Users\Windows\Desktop\twitterAnalyzer\CrawlingModule\search_tweets.py", line 180, in twitter_search
    next_results = search_results['search_metadata']['next_results']
KeyError: 'next_results'
2014-07-15 11:11:07,335 - search_tweets - ERROR - Failed to find attribute (WARRNING: might throw this exception for some results while searching in the loop)
Traceback (most recent call last):
  File "C:\Users\Windows\Desktop\twitterAnalyzer\CrawlingModule\search_tweets.py", line 180, in twitter_search
    next_results = search_results['search_metadata']['next_results']
KeyError: 'next_results'
2014-07-15 11:16:29,832 - search_tweets - ERROR - Failed to find attribute (WARRNING: might throw this exception for some results while searching in the loop)
Traceback (most recent call last):
  File "C:\Users\Windows\Desktop\twitterAnalyzer\CrawlingModule\search_tweets.py", line 180, in twitter_search
    next_results = search_results['search_metadata']['next_results']
KeyError: 'next_results'
2014-07-15 11:23:11,288 - search_tweets - ERROR - Failed to find attribute (WARRNING: might throw this exception for some results while searching in the loop)
Traceback (most recent call last):
  File "C:\Users\Windows\Desktop\twitterAnalyzer\CrawlingModule\search_tweets.py", line 180, in twitter_search
    next_results = search_results['search_metadata']['next_results']
KeyError: 'next_results'
2014-07-15 11:51:37,213 - search_tweets - ERROR - Failed to find attribute (WARRNING: might throw this exception for some results while searching in the loop)
Traceback (most recent call last):
  File "C:\Users\Windows\Desktop\twitterAnalyzer\CrawlingModule\search_tweets.py", line 180, in twitter_search
    next_results = search_results['search_metadata']['next_results']
KeyError: 'next_results'
2014-07-15 11:59:11,780 - search_tweets - ERROR - Failed to find attribute 
Traceback (most recent call last):
  File "C:\Users\Windows\Desktop\twitterAnalyzer\CrawlingModule\search_tweets.py", line 180, in twitter_search
    next_results = search_results['search_metadata']['next_results']
KeyError: 'next_results'
2014-07-15 11:59:54,138 - search_tweets - ERROR - Failed to find attribute 
Traceback (most recent call last):
  File "C:\Users\Windows\Desktop\twitterAnalyzer\CrawlingModule\search_tweets.py", line 180, in twitter_search
    next_results = search_results['search_metadata']['next_results']
KeyError: 'next_results'
2014-07-15 12:02:32,523 - search_tweets - ERROR - Failed to find attribute 
Traceback (most recent call last):
  File "C:\Users\Windows\Desktop\twitterAnalyzer\CrawlingModule\search_tweets.py", line 180, in twitter_search
    next_results = search_results['search_metadata']['next_results']
KeyError: 'next_results'
2014-07-15 12:02:59,342 - search_tweets - ERROR - Failed to find attribute 
Traceback (most recent call last):
  File "C:\Users\Windows\Desktop\twitterAnalyzer\CrawlingModule\search_tweets.py", line 180, in twitter_search
    next_results = search_results['search_metadata']['next_results']
KeyError: 'next_results'
2014-07-15 12:10:04,563 - search_tweets - ERROR - Failed to find attribute 
Traceback (most recent call last):
  File "C:\Users\Windows\Desktop\twitterAnalyzer\CrawlingModule\search_tweets.py", line 180, in twitter_search
    next_results = search_results['search_metadata']['next_results']
KeyError: 'next_results'
2014-07-15 12:12:51,625 - search_tweets - ERROR - Failed to find attribute 
Traceback (most recent call last):
  File "C:\Users\Windows\Desktop\twitterAnalyzer\CrawlingModule\search_tweets.py", line 182, in twitter_search
    next_results = search_results['search_metadata']['next_results']
KeyError: 'next_results'
2014-07-15 12:18:08,994 - search_tweets - ERROR - Failed to find attribute 
Traceback (most recent call last):
  File "C:\Users\Windows\Desktop\twitterAnalyzer\CrawlingModule\search_tweets.py", line 181, in twitter_search
    next_results = search_results['search_metadata']['next_results']
KeyError: 'next_results'
2014-07-15 12:19:47,640 - search_tweets - ERROR - Failed to find attribute 
Traceback (most recent call last):
  File "C:\Users\Windows\Desktop\twitterAnalyzer\CrawlingModule\search_tweets.py", line 181, in twitter_search
    next_results = search_results['search_metadata']['next_results']
KeyError: 'next_results'
2014-07-15 12:27:26,446 - search_tweets - ERROR - Failed to find attribute 
Traceback (most recent call last):
  File "C:\Users\Windows\Desktop\twitterAnalyzer\CrawlingModule\search_tweets.py", line 181, in twitter_search
    next_results = search_results['search_metadata']['next_results']
KeyError: 'next_results'
2014-07-15 12:28:03,798 - search_tweets - ERROR - Failed to find attribute 
Traceback (most recent call last):
  File "C:\Users\Windows\Desktop\twitterAnalyzer\CrawlingModule\search_tweets.py", line 181, in twitter_search
    next_results = search_results['search_metadata']['next_results']
KeyError: 'next_results'
2014-07-15 12:29:27,224 - search_tweets - ERROR - Failed to find attribute 
Traceback (most recent call last):
  File "C:\Users\Windows\Desktop\twitterAnalyzer\CrawlingModule\search_tweets.py", line 181, in twitter_search
    next_results = search_results['search_metadata']['next_results']
KeyError: 'next_results'
2014-07-15 12:36:43,450 - search_tweets - ERROR - Failed to find attribute 
Traceback (most recent call last):
  File "C:\Users\Windows\Desktop\twitterAnalyzer\CrawlingModule\search_tweets.py", line 181, in twitter_search
    next_results = search_results['search_metadata']['next_results']
KeyError: 'next_results'
2014-07-15 12:38:38,993 - search_tweets - ERROR - Failed to find attribute 
Traceback (most recent call last):
  File "C:\Users\Windows\Desktop\twitterAnalyzer\CrawlingModule\search_tweets.py", line 182, in twitter_search
    next_results = search_results['search_metadata']['next_results']
KeyError: 'next_results'
2014-07-15 12:41:08,611 - search_tweets - ERROR - Failed to find attribute 
Traceback (most recent call last):
  File "C:\Users\Windows\Desktop\twitterAnalyzer\CrawlingModule\search_tweets.py", line 182, in twitter_search
    next_results = search_results['search_metadata']['next_results']
KeyError: 'next_results'
2014-07-15 13:00:11,924 - search_tweets - ERROR - Failed to find attribute 
Traceback (most recent call last):
  File "C:\Users\Windows\Desktop\twitterAnalyzer\CrawlingModule\search_tweets.py", line 182, in twitter_search
    next_results = search_results['search_metadata']['next_results']
KeyError: 'next_results'
2014-07-15 13:50:13,167 - search_tweets - ERROR - Failed to find attribute 
Traceback (most recent call last):
  File "C:\Users\Windows\Desktop\twitterAnalyzer\CrawlingModule\search_tweets.py", line 182, in twitter_search
    next_results = search_results['search_metadata']['next_results']
KeyError: 'next_results'
2014-07-15 13:51:20,309 - search_tweets - ERROR - Failed to find attribute 
Traceback (most recent call last):
  File "C:\Users\Windows\Desktop\twitterAnalyzer\CrawlingModule\search_tweets.py", line 182, in twitter_search
    next_results = search_results['search_metadata']['next_results']
KeyError: 'next_results'
2014-07-15 13:52:14,971 - search_tweets - ERROR - Failed to find attribute 
Traceback (most recent call last):
  File "C:\Users\Windows\Desktop\twitterAnalyzer\CrawlingModule\search_tweets.py", line 182, in twitter_search
    next_results = search_results['search_metadata']['next_results']
KeyError: 'next_results'
2014-07-15 13:54:11,688 - search_tweets - ERROR - Failed to find attribute 
Traceback (most recent call last):
  File "C:\Users\Windows\Desktop\twitterAnalyzer\CrawlingModule\search_tweets.py", line 182, in twitter_search
    next_results = search_results['search_metadata']['next_results']
KeyError: 'next_results'
2014-07-15 13:59:12,183 - search_tweets - ERROR - Failed to find attribute 
Traceback (most recent call last):
  File "C:\Users\Windows\Desktop\twitterAnalyzer\CrawlingModule\search_tweets.py", line 183, in twitter_search
    next_results = search_results['search_metadata']['next_results']
KeyError: 'next_results'
2014-07-15 13:59:48,427 - search_tweets - ERROR - Failed to find attribute 
Traceback (most recent call last):
  File "C:\Users\Windows\Desktop\twitterAnalyzer\CrawlingModule\search_tweets.py", line 183, in twitter_search
    next_results = search_results['search_metadata']['next_results']
KeyError: 'next_results'
2014-07-15 15:40:49,438 - search_tweets - ERROR - Failed to find attribute 
Traceback (most recent call last):
  File "C:\Users\Windows\Desktop\twitterAnalyzer\CrawlingModule\search_tweets.py", line 181, in twitter_search
    next_results = search_results['search_metadata']['next_results']
KeyError: 'next_results'
2014-07-15 15:43:49,424 - search_tweets - ERROR - Failed to find attribute 
Traceback (most recent call last):
  File "C:\Users\Windows\Desktop\twitterAnalyzer\CrawlingModule\search_tweets.py", line 181, in twitter_search
    next_results = search_results['search_metadata']['next_results']
KeyError: 'next_results'
2014-07-15 16:30:18,802 - search_tweets - ERROR - Failed to find attribute 
Traceback (most recent call last):
  File "C:\Users\Windows\Desktop\twitterAnalyzer\CrawlingModule\search_tweets.py", line 170, in twitter_search
    next_results = search_results['search_metadata']['next_results']
KeyError: 'next_results'
2014-07-15 16:30:48,744 - search_tweets - ERROR - Failed to find attribute 
Traceback (most recent call last):
  File "C:\Users\Windows\Desktop\twitterAnalyzer\CrawlingModule\search_tweets.py", line 170, in twitter_search
    next_results = search_results['search_metadata']['next_results']
KeyError: 'next_results'
2014-07-15 17:06:22,776 - debugging_setup - ERROR - Failed to find attribute 
Traceback (most recent call last):
  File "C:\Users\Windows\Desktop\twitterAnalyzer\CrawlingModule\search_tweets.py", line 137, in twitter_search
    next_results = search_results['search_metadata']['next_results']
KeyError: 'next_results'
2014-07-15 17:06:22,776 - debugging_setup - ERROR - Failed to find attribute 
Traceback (most recent call last):
  File "C:\Users\Windows\Desktop\twitterAnalyzer\CrawlingModule\search_tweets.py", line 137, in twitter_search
    next_results = search_results['search_metadata']['next_results']
KeyError: 'next_results'
2014-07-15 17:06:22,776 - debugging_setup - ERROR - Failed to find attribute 
Traceback (most recent call last):
  File "C:\Users\Windows\Desktop\twitterAnalyzer\CrawlingModule\search_tweets.py", line 137, in twitter_search
    next_results = search_results['search_metadata']['next_results']
KeyError: 'next_results'
2014-07-15 17:06:22,776 - debugging_setup - ERROR - Failed to find attribute 
Traceback (most recent call last):
  File "C:\Users\Windows\Desktop\twitterAnalyzer\CrawlingModule\search_tweets.py", line 137, in twitter_search
    next_results = search_results['search_metadata']['next_results']
KeyError: 'next_results'
2014-07-15 17:12:11,309 - debugging_setup - ERROR - Failed to find attribute 
Traceback (most recent call last):
  File "C:\Users\Windows\Desktop\twitterAnalyzer\CrawlingModule\search_tweets.py", line 137, in twitter_search
    next_results = search_results['search_metadata']['next_results']
KeyError: 'next_results'
2014-07-15 17:12:11,309 - debugging_setup - ERROR - Failed to find attribute 
Traceback (most recent call last):
  File "C:\Users\Windows\Desktop\twitterAnalyzer\CrawlingModule\search_tweets.py", line 137, in twitter_search
    next_results = search_results['search_metadata']['next_results']
KeyError: 'next_results'
2014-07-15 17:12:11,309 - debugging_setup - ERROR - Failed to find attribute 
Traceback (most recent call last):
  File "C:\Users\Windows\Desktop\twitterAnalyzer\CrawlingModule\search_tweets.py", line 137, in twitter_search
    next_results = search_results['search_metadata']['next_results']
KeyError: 'next_results'
2014-07-15 17:12:11,309 - debugging_setup - ERROR - Failed to find attribute 
Traceback (most recent call last):
  File "C:\Users\Windows\Desktop\twitterAnalyzer\CrawlingModule\search_tweets.py", line 137, in twitter_search
    next_results = search_results['search_metadata']['next_results']
KeyError: 'next_results'
2014-07-15 17:12:11,309 - debugging_setup - ERROR - Failed to find attribute 
Traceback (most recent call last):
  File "C:\Users\Windows\Desktop\twitterAnalyzer\CrawlingModule\search_tweets.py", line 137, in twitter_search
    next_results = search_results['search_metadata']['next_results']
KeyError: 'next_results'
2014-07-15 17:13:26,970 - debugging_setup - ERROR - Failed to find attribute 
Traceback (most recent call last):
  File "C:\Users\Windows\Desktop\twitterAnalyzer\CrawlingModule\search_tweets.py", line 137, in twitter_search
    next_results = search_results['search_metadata']['next_results']
KeyError: 'next_results'
2014-07-15 17:13:26,970 - debugging_setup - ERROR - Failed to find attribute 
Traceback (most recent call last):
  File "C:\Users\Windows\Desktop\twitterAnalyzer\CrawlingModule\search_tweets.py", line 137, in twitter_search
    next_results = search_results['search_metadata']['next_results']
KeyError: 'next_results'
2014-07-15 17:13:26,970 - debugging_setup - ERROR - Failed to find attribute 
Traceback (most recent call last):
  File "C:\Users\Windows\Desktop\twitterAnalyzer\CrawlingModule\search_tweets.py", line 137, in twitter_search
    next_results = search_results['search_metadata']['next_results']
KeyError: 'next_results'
2014-07-15 17:13:26,970 - debugging_setup - ERROR - Failed to find attribute 
Traceback (most recent call last):
  File "C:\Users\Windows\Desktop\twitterAnalyzer\CrawlingModule\search_tweets.py", line 137, in twitter_search
    next_results = search_results['search_metadata']['next_results']
KeyError: 'next_results'
2014-07-15 17:13:26,970 - debugging_setup - ERROR - Failed to find attribute 
Traceback (most recent call last):
  File "C:\Users\Windows\Desktop\twitterAnalyzer\CrawlingModule\search_tweets.py", line 137, in twitter_search
    next_results = search_results['search_metadata']['next_results']
KeyError: 'next_results'
2014-07-15 17:37:55,430 - debugging_setup - ERROR - Failed to find attribute 
Traceback (most recent call last):
  File "C:\Users\Windows\Desktop\twitterAnalyzer\CrawlingModule\search_tweets.py", line 137, in twitter_search
    next_results = search_results['search_metadata']['next_results']
KeyError: 'next_results'
2014-07-15 17:37:55,430 - debugging_setup - ERROR - Failed to find attribute 
Traceback (most recent call last):
  File "C:\Users\Windows\Desktop\twitterAnalyzer\CrawlingModule\search_tweets.py", line 137, in twitter_search
    next_results = search_results['search_metadata']['next_results']
KeyError: 'next_results'
2014-07-15 17:37:55,430 - debugging_setup - ERROR - Failed to find attribute 
Traceback (most recent call last):
  File "C:\Users\Windows\Desktop\twitterAnalyzer\CrawlingModule\search_tweets.py", line 137, in twitter_search
    next_results = search_results['search_metadata']['next_results']
KeyError: 'next_results'
2014-07-15 17:37:55,430 - debugging_setup - ERROR - Failed to find attribute 
Traceback (most recent call last):
  File "C:\Users\Windows\Desktop\twitterAnalyzer\CrawlingModule\search_tweets.py", line 137, in twitter_search
    next_results = search_results['search_metadata']['next_results']
KeyError: 'next_results'
2014-07-15 17:37:55,430 - debugging_setup - ERROR - Failed to find attribute 
Traceback (most recent call last):
  File "C:\Users\Windows\Desktop\twitterAnalyzer\CrawlingModule\search_tweets.py", line 137, in twitter_search
    next_results = search_results['search_metadata']['next_results']
KeyError: 'next_results'
2014-07-15 17:40:05,142 - debugging_setup - ERROR - Failed to find attribute 
Traceback (most recent call last):
  File "C:\Users\Windows\Desktop\twitterAnalyzer\CrawlingModule\search_tweets.py", line 137, in twitter_search
    next_results = search_results['search_metadata']['next_results']
KeyError: 'next_results'
2014-07-15 17:40:05,142 - debugging_setup - ERROR - Failed to find attribute 
Traceback (most recent call last):
  File "C:\Users\Windows\Desktop\twitterAnalyzer\CrawlingModule\search_tweets.py", line 137, in twitter_search
    next_results = search_results['search_metadata']['next_results']
KeyError: 'next_results'
2014-07-15 17:40:05,142 - debugging_setup - ERROR - Failed to find attribute 
Traceback (most recent call last):
  File "C:\Users\Windows\Desktop\twitterAnalyzer\CrawlingModule\search_tweets.py", line 137, in twitter_search
    next_results = search_results['search_metadata']['next_results']
KeyError: 'next_results'
2014-07-15 17:40:05,142 - debugging_setup - ERROR - Failed to find attribute 
Traceback (most recent call last):
  File "C:\Users\Windows\Desktop\twitterAnalyzer\CrawlingModule\search_tweets.py", line 137, in twitter_search
    next_results = search_results['search_metadata']['next_results']
KeyError: 'next_results'
2014-07-15 17:40:05,142 - debugging_setup - ERROR - Failed to find attribute 
Traceback (most recent call last):
  File "C:\Users\Windows\Desktop\twitterAnalyzer\CrawlingModule\search_tweets.py", line 137, in twitter_search
    next_results = search_results['search_metadata']['next_results']
KeyError: 'next_results'
2014-07-15 17:40:34,118 - debugging_setup - ERROR - Failed to find attribute 
Traceback (most recent call last):
  File "C:\Users\Windows\Desktop\twitterAnalyzer\CrawlingModule\search_tweets.py", line 137, in twitter_search
    next_results = search_results['search_metadata']['next_results']
KeyError: 'next_results'
2014-07-15 17:40:34,118 - debugging_setup - ERROR - Failed to find attribute 
Traceback (most recent call last):
  File "C:\Users\Windows\Desktop\twitterAnalyzer\CrawlingModule\search_tweets.py", line 137, in twitter_search
    next_results = search_results['search_metadata']['next_results']
KeyError: 'next_results'
2014-07-15 17:40:34,118 - debugging_setup - ERROR - Failed to find attribute 
Traceback (most recent call last):
  File "C:\Users\Windows\Desktop\twitterAnalyzer\CrawlingModule\search_tweets.py", line 137, in twitter_search
    next_results = search_results['search_metadata']['next_results']
KeyError: 'next_results'
2014-07-15 17:40:34,118 - debugging_setup - ERROR - Failed to find attribute 
Traceback (most recent call last):
  File "C:\Users\Windows\Desktop\twitterAnalyzer\CrawlingModule\search_tweets.py", line 137, in twitter_search
    next_results = search_results['search_metadata']['next_results']
KeyError: 'next_results'
2014-07-15 17:40:34,118 - debugging_setup - ERROR - Failed to find attribute 
Traceback (most recent call last):
  File "C:\Users\Windows\Desktop\twitterAnalyzer\CrawlingModule\search_tweets.py", line 137, in twitter_search
    next_results = search_results['search_metadata']['next_results']
KeyError: 'next_results'
2014-07-16 10:18:47,489 - debugging_setup - ERROR - Failed to open file
Traceback (most recent call last):
  File "H:\twitterAnalyzer\CrawlingModule\authorization.py", line 34, in oauth_login
    oauth_token, oauth_token_secret = read_token_file(OAUTH_FILE)
  File "C:\Python27\lib\site-packages\twitter\oauth.py", line 74, in read_token_file
    f = open(filename)
IOError: [Errno 2] No such file or directory: 'C:/Users/Windows/Desktop/twitterAnalyzer/CrawlingModule/Resources/twitter_oauth.txt'
2014-07-16 10:18:47,489 - debugging_setup - ERROR - Failed to open file
Traceback (most recent call last):
  File "H:\twitterAnalyzer\CrawlingModule\authorization.py", line 34, in oauth_login
    oauth_token, oauth_token_secret = read_token_file(OAUTH_FILE)
  File "C:\Python27\lib\site-packages\twitter\oauth.py", line 74, in read_token_file
    f = open(filename)
IOError: [Errno 2] No such file or directory: 'C:/Users/Windows/Desktop/twitterAnalyzer/CrawlingModule/Resources/twitter_oauth.txt'
2014-07-16 10:18:47,489 - debugging_setup - ERROR - Failed to open file
Traceback (most recent call last):
  File "H:\twitterAnalyzer\CrawlingModule\authorization.py", line 34, in oauth_login
    oauth_token, oauth_token_secret = read_token_file(OAUTH_FILE)
  File "C:\Python27\lib\site-packages\twitter\oauth.py", line 74, in read_token_file
    f = open(filename)
IOError: [Errno 2] No such file or directory: 'C:/Users/Windows/Desktop/twitterAnalyzer/CrawlingModule/Resources/twitter_oauth.txt'
2014-07-16 10:18:47,489 - debugging_setup - ERROR - Failed to open file
Traceback (most recent call last):
  File "H:\twitterAnalyzer\CrawlingModule\authorization.py", line 34, in oauth_login
    oauth_token, oauth_token_secret = read_token_file(OAUTH_FILE)
  File "C:\Python27\lib\site-packages\twitter\oauth.py", line 74, in read_token_file
    f = open(filename)
IOError: [Errno 2] No such file or directory: 'C:/Users/Windows/Desktop/twitterAnalyzer/CrawlingModule/Resources/twitter_oauth.txt'
